# 概述

Rust 的可靠性同样在错误处理方面可以提现，大部分的错误可以在编译的时候就提示出来，并告知工程师处理，错误的分类：

- 可恢复 - 文件未找到，可再次尝试 >>> `Result<T, E>`
- 不可恢复 - 访问的索引超出范围 >>> `panic!`

Rust 没有类似 `异常` 的机制。



# 1. 不可恢复

当 `panic!` 执行的时候，程序会打印一个错误信息，并展开，清理调用栈，最后退出程序。默认情况下分下面几步

1. 程序展开调用栈
2. 沿着调用栈回溯程序
3. 逐一清理每一个遇到再函数中的数据

如果是立即终止，则直接停止程序，数据不清理了，内存由操作系统自行清理。这两种情况最终输出的二进制文件大小是不同的，`abort` 是更小的，可以这么设置直接立即终止：

```toml
[package]
...

[dependencies]
...

[profile.release]
panic = 'abort'
```

在程序中引发 `panic!` 很简单，如下代码：

```rust
fn main() {
  panic!("crash and burn");
}
```

这时候就会有一堆错误讯息在 `cargo run` 之后被打印出来。



## 错误追溯

有些时候 panic 并非我们自己引起的，有些 panic 是嵌入在调用的其他函数中的，为了更好的定位到底具体是哪一行引发了 panic，可以设置环境变量 `RUST_BACKTRACE` 来获取回溯信息：

```bash
set RUST_BACKTRACE=1 && cargo run
```

这时候就有更详细的错误信息被返回，如果觉得还不够的话，可以用 `full` 取代 `1`：

```bash
set RUST_BACKTRACE=full && cargo run
```

但是要注意，如果想把错误信息都显示出来，切记 `cargo run` 后面不能加上 `--release`。



# 2. 可恢复

 大部分情况下，错误都不会是必须把程序停掉的地步，因此 `Result` 枚举成了一个很重要的处理手段。

```rust
enum Result<T, E> {
  Ok(T),
  Err(E),
}
```

+ T：操作成功，Ok 变体里返回数据的类型
+ E：操作失败，Err 变体里返回错误的类型

例如我们要打开一个文件，但这个文件不存在，所以就会报错：

```rust
use std::fs::File;

fn main() {
  let f = File::open("hello.txt");
}
```

处理可能遇到错误的情况的方法就是 match 表达式，和 `Option` 枚举一样，`Result` 及其变体也是由 prelude 带入作用域，上述程序就可以扩写成下面内容：

```rust
use std::fs::File;

fn main() {
  let f = File::open("hello.txt");
  
  let f = match f {
    Ok(file) => file,
    Err(error) => {
      panic!("Error opening file {:?}", error);
    }
  };
}
```

不过这个例子单独只读取文件，失败了就失败了，但如果失败了我们想进一步创建文件，则可以继续这样扩写：

```rust
use std::fs::File;
use std::io::ErrorKind;

fn main() {
  let f = File::open("hello.txt");
  
  let f = match f {
    Ok(file) => file,
    Err(error) => match error.kind() {
      ErrorKind::NotFound => match File::create("hello.txt") {
        Ok(fc) => fc,
        Err(e) => panic!("Error creating file {:?}", e),
      },
      other_error => panic!("Error opening file {:?}", other_error),
    },
  };
}
```



## 匹配不同的错误

虽然上面看到我们使用 match 确实做到了效果，但是很繁琐也很原始，有一个更好用的方法：闭包 (closure) 可以更好的改写上面的原始代码。

```rust
let f = File::open("hello.txt").unwrap_or_else(|error| {
  if error.kind() == ErrorKind::NotFound {
    File::create("hello.txt").unwrape_or_else(|error| {
      panic!("Error creating file: {:?}", error);
    })
  } else {
    panic!("Error opening file: {:?}", error)
  }
});
```

除了 `unwraps_or_else` 方法之外，还有 `unwrape` 也很好用，是一种 match 表达式的快捷方法，如果 Result 结果 Ok，则返回 Ok 的值，反之如果是 Err，则调用 `panic!` 宏。

```rust
fn main() {
  // let f = File::open("hello.txt");
  
  // let f = match f {
  //   Ok(file) => file,
  //   Err(error) => {
  //     panic!("Error opening file {:?}", error);
  //   }
  // };
  
  let f = File::open("hello.txt").unwrape();
}
```

不过 `unwrape` 也有缺点，就是无法自己决定错误了之后要打印什么内容出来，如果使用 `expect` 的话就可以解决这个问题

```rust
fn main() {
  let f = File::open("hello.txt").expect("Error msg !");
}
```



## 传播错误

除了可以在函数中处理错误之外，还可以将这个错误返回给调用函数的物件，然后让这个物件来决定如何处理错误，例如本来下面这个复杂的代码：

```rust
use std::fs::File;
use std::io::{self, Read};

fn read_username_from_file() -> Result<String, io::Error> {
  let f = File::open("hello.txt");
  
  let mut f = match f {
    Ok(file) => file,
    Err(e) => return Err(e),
  };
  
  let mut s = String::new();
  match f.read_to_string(&mut s) {
    Ok(_) => Ok(s),
    Err(e) => Err(e),
  }
}
```

可以用 `?` 来简化代码的写法成：

```rust
fn read_username_from_file() -> Result<String, io::Error> {
  let mut f = File::open("hello.txt")?;
  
  let mut s = String::new();
  f.read_to_string(&mut s)?;
  Ok(s)
}
```

用法就是如果成功就继续接着执行，如果失败就返回 `Err`。而且其实这种写法可以通过链式调用进一步压缩代码：

```rust
fn read_username_from_file() -> Result<String, io::Error> {
  let mut s = String::new();
  File::open("hello.txt")?.read_to_string(&mut s)?;
  Ok(s)
}
```

这种操作错误的方式也可以直接在 main 函数中使用，只不过需要将函数返回类型也是调整成 Result，其中 `Box<dyn Error>` 是一个 trait 对象，可以用来归纳任何错误类型。

```rust
use std::fs::File;
use std::error::Error;

fn main() -> Result<(), Box<dyn Error>> {
  let f = File::open("hello.txt")?;
  ok(())
}
```



# 总结

当你认为遇到某种情况可以替代调用者决定是否停止程序的时候，就可以使用 `panic!` 来彻底停止程序，否则错误信息的处理权就是交给代码的调用者来管理。



## 错误处理建议

当代码最终可能处于损坏状态，例如某些假设，保证，约定，或不可变形被打破时，最好使用 `panic!`，例如非法，矛盾，空缺的值，以及：

1. 损坏状态并不是预期能够偶尔发生的事情
2. 如果代码处在这种损坏状态就无法运行
3. 使用的类型中没有一个好的方法处理这个数据的时候

